Workbook

Sheet 요약
A1: ReelCut 개발 일지
A3: 로드맵 항목 수 | B3: =COUNTA(로드맵!B2:B40) -> 39
A4: 완료 | B4: =COUNTIF(로드맵!E2:E40,"완료") -> 35
A5: 진행 중 | B5: =COUNTIF(로드맵!E2:E40,"진행 중") -> 0
A6: 대기 | B6: =COUNTIF(로드맵!E2:E40,"대기") -> 4
A7: 진행률 | B7: =IFERROR(B4/B3,0) -> 0.8974359
A9: 기록 수 | B9: =COUNTA('개발 기록'!C2:C60) -> 59
A10: 사용자 제보 처리 | B10: =COUNTIF('개발 기록'!B2:B60,"사용자 제보") -> 5
A11: 최근 테스트 수 | B11: =INDEX(테스트!B2:B33,32) -> 107
A12: 최근 테스트 통과 | B12: =INDEX(테스트!C2:C33,32) -> 107
A14: 우선순위 기준
A15: 기준 1 | B15: 작업이 날아가거나 결과물이 잘못 나오는 문제 (데이터 손실·오동작)
A16: 기준 2 | B16: 사용자가 직접 겪고 알려준 불편
A17: 기준 3 | B17: 매번 쓰는 흐름(편집 → 미리보기 → 내보내기)의 체감 속도·편의
A18: 기준 4 | B18: 결과물 완성도를 높이는 새 기능

Sheet 로드맵
A1: 순위 | B1: 항목 | C1: 기준 | D1: 이유 | E1: 상태 | F1: 완료일
A2: 1 | B2: 렌더링 병렬화 (조각을 여러 개 동시에 인코딩) | C2: 기준 3 | D2: 비트 맞춤은 조각이 수백 개라 느림 (기준 정하기 전에 시작) | E2: 완료 | F2: 2026-10-28
A3: 2 | B3: 자동 저장 + 다음 실행 때 복구 | C3: 기준 1 | D3: 실수로 닫거나 오류로 꺼지면 작업이 날아감 | E3: 완료 | F3: 2026-10-28
A4: 3 | B4: 취소·오류 처리 다듬기 (취소 시 파일 보호, 옮겨진 파일 다시 연결, 쉬운 오류 문구) | C4: 기준 1 | D4: 최종 단계에서 취소하면 깨진 파일이 남고 기존 영상이 덮어써짐 | E4: 완료 | F4: 2026-10-28
A5: 4 | B5: 진행률에 남은 시간 표시 | C5: 기준 3 | D5: 긴 렌더링에서 언제 끝날지 알 수 없음 | E5: 완료 | F5: 2026-10-28
A6: 5 | B6: 클립 목록 썸네일 | C6: 기준 3 | D6: 파일 이름만으로는 어떤 영상인지 구분이 어려움 | E6: 완료 | F6: 2026-10-28
A7: 6 | B7: 음량 자동 맞춤 (유튜브/릴스 권장 음량) | C7: 기준 4 | D7: 노래·원본 소리 크기가 들쭉날쭉 | E7: 완료 | F7: 2026-10-28
A8: 7 | B8: 영상 시작/끝 페이드 인·아웃 | C8: 기준 4 | D8: 갑자기 시작·끝나는 느낌 완화 | E8: 완료 | F8: 2026-10-28
A9: 8 | B9: 비트 컷 전환 효과 (짧은 플래시/줌 등) | C9: 기준 4 | D9: 비트 맞춤 영상의 완성도 | E9: 완료 | F9: 2026-10-28
A10: 9 | B10: 제목 텍스트 넣기 | C10: 기준 4 | D10: 자막과 별개로 큰 제목이 필요한 경우 | E10: 완료 | F10: 2026-10-28
A11: 10 | B11: 내보내기 전 디스크 공간 확인 + 내보낸 뒤 결과 자동 검사(길이·화면 크기·소리) | C11: 기준 1 | D11: 오래 걸린 렌더가 끝에서 공간 부족으로 실패하거나, 잘못된 결과를 모르고 올리는 일 방지 | E11: 완료 | F11: 2026-10-28
A12: 11 | B12: 실행 취소 / 다시 실행 (Ctrl+Z / Ctrl+Y) | C12: 기준 1 | D12: 클립을 실수로 지우면 자르기 설정까지 날아감 | E12: 완료 | F12: 2026-10-28
A13: 12 | B13: 미리보기·결과를 Windows 기본 플레이어로 열기 버튼 | C13: 기준 2 | D13: '노래 늘어짐' 제보: 앱 재생기 문제인지 파일 문제인지 바로 가를 수 있게 | E13: 완료 | F13: 2026-10-28
... A15: 14 | B15: 클립별 소리 크기·음소거, 재생 속도 | C15: 기준 4 | D15: 클립마다 원본 소리 크기가 달라 개별 조절이 필요 | E15: 완료 | F15: 2026-10-28
A16: 15 | B16: 자동 자막 실제 모델로 검증 (Windows에서 첫 다운로드·한국어 인식) | C16: 기준 1 | D16: 이 서버에서는 모델을 받을 수 없어 가짜 모델로만 확인함 | E16: 대기
A17: 16 | B17: 미리보기 재생기 소리 늘어짐 원인 확정 (사용자 확인 결과에 따라) | C17: 기준 2 | D17: 외부 플레이어 비교 결과를 받아서 결정 | E17: 대기
A18: 17 | B18: 타임라인 막대 (완성 영상에서 각 클립·컷 위치를 한눈에) | C18: 기준 3 | D18: 클립이 많아지면 목록만으로는 전체 흐름이 안 보임 | E18: 완료 | F18: 2026-10-28
A19: 18 | B19: 비트 강약 반영 (센 비트에서만 컷 / 후렴구에서 더 빠르게) | C19: 기준 4 | D19: 모든 비트에서 똑같이 바뀌면 단조로움 | E19: 완료 | F19: 2026-10-28
A20: 19 | B20: 오류 기록 파일 + 예상 못한 오류 안내 창 | C20: 기준 1 | D20: 사용자 PC에서 생긴 문제를 원인까지 추적할 방법이 없음 (지금은 메시지 한 줄뿐) | E20: 완료 | F20: 2026-10-28
A21: 20 | B21: 클립 개수 × N초로 영상 길이 정하기 (클립마다 한 컷, 노래도 거기서 끝) | C21: 기준 2 | D21: 사용자 요청: 8개 영상을 N초씩 이으면 8×N초에 끝나야 함 | E21: 완료 | F21: 2026-10-28
A22: 21 | B22: 대규모 프로젝트 스트레스 테스트 (컷 수백 개·10분 영상) | C22: 기준 1 | D22: 실제 사용은 테스트보다 훨씬 길고 컷이 많음 | E22: 완료 | F22: 2026-10-28
A23: 22 | B23: 단축키 (스페이스 재생, Delete 삭제, 미리보기·내보내기) | C23: 기준 3 | D23: 자주 하는 동작을 마우스 없이 | E23: 완료 | F23: 2026-10-28
A24: 23 | B24: 사진 켄 번즈 효과 (천천히 확대·이동) | C24: 기준 4 | D24: 사진이 멈춰 있으면 영상이 밋밋함 | E24: 완료 | F24: 2026-10-28
A25: 24 | B25: 말소리 나올 때 음악 자동 줄이기 (덕킹) | C25: 기준 4 | D25: 브이로그에서 음악에 말소리가 묻힘 | E25: 완료 | F25: 2026-10-28
A26: 25 | B26: 색감 필터 (따뜻하게·차갑게·흑백·선명하게·빈티지) | C26: 기준 4 | D26: 여러 폰으로 찍은 영상의 색감 통일·분위기 | E26: 완료 | F26: 2026-10-28
A27: 26 | B27: 그래픽카드 인코딩 (NVIDIA·Intel·AMD) 자동 사용 | C27: 기준 3 | D27: 내보내기가 가장 오래 걸리는 단계 — 그래픽카드가 있는 PC에서 체감 속도가 크게 좋아짐 | E27: 완료 | F27: 2026-10-28
A28: 27 | B28: 릴스·유튜브 한 번에 둘 다 내보내기 | C28: 기준 3 | D28: 같은 영상을 비율만 바꿔 두 번 올리는 경우가 많음 — 설정 바꾸고 다시 내보내는 반복을 줄임 | E28: 완료 | F28: 2026-10-28
A29: 28 | B29: 대표 이미지(썸네일) 저장 | C29: 기준 4 | D29: 유튜브 업로드에 필요 — 미리보기에서 원하는 장면을 바로 이미지로 | E29: 완료 | F29: 2026-10-28
... A38: 37 | B38: 클립마다 날짜 도장 (예: 2026.03.14) | C38: 기준 4 | D38: recap 릴스의 대표 연출 — 언제 장면인지 보여 줌 | E38: 완료 | F38: 2026-10-28
A39: 38 | B39: 월별 제목 자동 만들기 (JANUARY, FEBRUARY …) | C39: 기준 3 | D39: 1년치 영상의 구간 나누기를 손으로 하면 오래 걸림 | E39: 대기
A40: 39 | B40: 폴더 추가 때 날짜 범위로 고르기 (예: 2026년만) | C40: 기준 3 | D40: 카메라 앨범 폴더엔 다른 해 사진도 섞여 있음 | E40: 대기

Sheet 개발 기록
A1: 날짜 | B1: 구분 | C1: 항목 | D1: 내용 | E1: 결과 | F1: 커밋
A2: 2026-10-13 | B2: 기능 | C2: 첫 버전 | D2: 이어붙이기, 자동 자막(Whisper), 비트 맞춤 컷, 화면 속 화면, 내보내기 | E2: 완료 | F2: 4dd839b
A3: 2026-10-13 | B3: 기능 | C3: 유튜브 링크 → mp3, 음악 시작 위치 파형 게이지 | D3: yt-dlp + Deno 포함, 클릭/드래그로 시작 위치, 미리듣기 | E3: 완료 | F3: 77306ce
A4: 2026-10-13 | B4: 수정 | C4: Windows 빌드 실패 | D4: FFmpeg 다운로드 주소가 없어진 파일을 가리킴 → master-latest로 변경 | E4: 빌드 성공 | F4: 77306ce
A5: 2026-10-13 | B5: 기능 | C5: 자막 글꼴 지정 | D5: 글꼴 파일 불러오기, 색·굵게·상자·위치, 미리보기. 위/가운데 정렬 번호 오류도 수정 | E5: 완료 | F5: 40a61f7
A6: 2026-10-13 | B6: 기능 | C6: 화면 비율 선택 | D6: 16:9 / 9:16 / 1:1 / 4:5, 흐린 배경·잘라 채우기·검은 여백 | E6: 완료 | F6: beef089
A7: 2026-10-13 | B7: 사용자 제보 | C7: 비트 맞춤인데 장면 전환이 안 됨 | D7: 원인: '차례대로'가 클립을 끊김 없이 이어 자름 + 음악보다 긴 부분이 한 덩어리. 클립 안에서 건너뛰도록, 음악 길이로 제한 | E7: 수정 | F7: f2c1d9b
A8: 2026-10-13 | B8: 사용자 제보 | C8: 같은 파일 안에서만 건너뜀 | D8: 컷마다 다음 파일로 넘어가는 '파일 번갈아'를 기본으로, '몰아서'·'무작위'·'이어서(예전 방식)' 선택지 | E8: 수정 | F8: 8c0d897
A9: 2026-10-13 | B9: 사용자 제보 | C9: 헤드폰인데 스피커로 나옴 / 노래가 늘어짐 | D9: 출력 장치 선택 + 기본 장치 자동 따라가기 추가. 렌더 결과물은 원곡과 0초 오차로 확인 → 재생기 출력 장치 문제로 추정 | E9: 확인 대기 | F9: 023a344
A10: 2026-10-28 | B10: 테스트 | C10: 엣지 케이스 렌더링 | D10: 한글·따옴표·대괄호 경로, 10비트 HEVC 60fps, VP9, 홀수 해상도·yuv444p, 모노 22kHz, 3000×4000 사진, 회전 메타데이터 세로 영상, 자막 특수문자 — 5가지 조합 | E10: 모두 통과
A11: 2026-10-28 | B11: 기능 | C11: [1순위] 렌더링 병렬화 | D11: 조각 인코딩을 동시에 실행(코어 절반, 최대 4). 4코어·30초·1080×1920·컷 36개: 45.7초 → 22.0초(2개) → 20.5초(4개). 실패·취소 시 모두 중단 | E11: 약 2배 빨라짐 | F11: 1e76e71
A12: 2026-10-28 | B12: 기능 | C12: [2순위] 자동 저장 + 복구 | D12: 편집 3초 뒤 별도 위치에 자동 저장, 다음 실행 때 복구 여부 확인. 프로젝트 저장을 원자적 쓰기로 변경 | E12: 완료 | F12: c51451b
A13: 2026-10-28 | B13: 수정 | C13: [3순위] 취소 시 기존 영상이 깨지는 문제 | D13: 최종 인코딩을 임시 파일에 쓰고 성공했을 때만 이름을 바꿈. 취소·오류 시 기존 파일 그대로, 임시 파일 정리 | E13: 완료 | F13: 332d576
A14: 2026-10-28 | B14: 기능 | C14: [3순위] 없어진 파일 확인·다시 연결, 쉬운 오류 문구 | D14: 렌더 전 없는 파일 목록 표시, 폴더를 고르면 같은 이름으로 찾아 다시 연결. 디스크 부족·권한·손상 파일 등은 한글 설명 | E14: 완료 | F14: 332d576
A15: 2026-10-28 | B15: 테스트 | C15: [3순위] 다시 연결 화면 흐름 | D15: 클립을 다른 폴더로 옮긴 프로젝트 열기 → '폴더에서 찾기' → 하위 폴더에서 찾아 연결, 렌더 전에도 같은 확인 | E15: 통과
A16: 2026-10-28 | B16: 기능 | C16: 개발 일지 엑셀 | D16: devlog.json 한 곳에 기록 → tools/make_devlog.py가 DEVLOG.xlsx(요약·로드맵·개발 기록·테스트)와 DEVLOG.md 생성 | E16: 완료 | F16: 332d576
A17: 2026-10-28 | B17: 기능 | C17: [4순위] 남은 시간 표시 | D17: 상태줄에 '남은 시간 약 1분 30초' 표시 (시작 3초·3% 이후부터). 1·2단계 실제 시간 비율을 재서 진행률 배분 조정: 내보내기 50:50, 미리보기 75:25 (실측 0.52 / 0.75 / 0.42) | E17: 완료 | F17: af939c2
A18: 2026-10-28 | B18: 기능 | C18: [5순위] 클립 목록 썸네일 | D18: 영상마다 시작점에서 조금 뒤(최대 1초) 장면을 뒤에서 만들어 목록에 표시. 자르기 시작점을 바꾸면 썸네일도 바뀜. HEVC·VP9·회전 영상·사진에서 확인 | E18: 완료 | F18: 612e0d2
A19: 2026-10-28 | B19: 기능 | C19: [6순위] 음량 자동 맞춤 | D19: 최종 소리에 loudnorm(-14 LUFS, 최대 -1.5 dBTP) 적용, 내보내기의 '음량 자동 맞춤' 체크(기본 켬). 측정: 노래 10% → -13.5 LUFS, 노래 200% → -13.5 LUFS, 끔 → -16.0 LUFS | E19: 완료 | F19: 4cb720f
A20: 2026-10-28 | B20: 기능 | C20: [7순위] 시작·끝 페이드 | D20: 내보내기 '시작·끝' 선택: 없음 / 끝만 사라지기 / 짧게 0.5초 / 길게 1.5초. 영상은 검은 화면으로, 소리도 함께. 측정: 밝기 19 → 126 → 21 (페이드 1초/1.5초) | E20: 완료 | F20: 3619d50
A21: 2026-10-28 | B21: 기능 | C21: [8순위] 비트 컷 전환 효과 | D21: 음악·비트 탭 '컷 전환 효과': 없음 / 번쩍(흰 플래시 0.15초) / 줌 펀치(12% 확대 → 0.3초에 원래대로) / 검은 깜빡임(0.12초). 첫 조각에는 효과 없음 | E21: 완료 | F21: 873f50a
A22: 2026-10-28 | B22: 버그 | C22: 번쩍 효과에서 끝 0.17초 잘림 + 색 바램 | D22: 원인: 번쩍 효과 조각만 yuv444p로 저장 → 이어붙일 때 조각 경계마다 필터가 재시작되며 시간이 꼬임(소리 0.36초 늦게 시작/끝 잘림). 해결: 모든 조각을 yuv420p·같은 색 범위로 강제, 이어붙인 뒤 프레임 번호로 시간 재계산, 출력 -t 대신 필터에서 길이 맞춤. 회귀 테스트 추가. 색 정보가 다른 폰 영상 섞기는 수정 전에도 문제없음을 확인(사용자 '늘어짐' 제보와는 무관) | E22: 수정 | F22: 873f50a
A23: 2026-10-28 | B23: 기능 | C23: [9순위] 제목 텍스트 | D23: '🔤 제목' 탭: 시간·문구 표(여러 개, \n 줄바꿈), 글꼴(설치/파일), 크기(화면 높이 %), 굵게, 글자·외곽선 색, 위치(가운데/위/아래), 나타나는 시간. ASS 자막으로 그려 자막과 함께 써도 겹치지 않음. 괄호·역슬래시 등 특수문자 처리 | E23: 완료 | F23: 6ed8179
A24: 2026-10-28 | B24: 계획 | C24: 1차 로드맵 완료 → 2차 로드맵(10~14순위) 수립 | D24: 같은 우선순위 기준으로, 테스트 중 발견한 위험·불편을 정리
A25: 2026-10-28 | B25: 기능 | C25: [10순위] 디스크 공간 확인 + 결과 자동 검사 | D25: 렌더 시작 전 임시 폴더·저장 폴더 드라이브의 남은 공간을 추정치와 비교해 부족하면 바로 알림(같은 드라이브면 합산, 실측의 약 2.5배로 넉넉히). 내보낸 뒤 결과를 다시 열어 영상·소리 트랙, 화면 크기, 길이를 확인하고 이상하면 경고 | E25: 완료 | F25: 615470e
A26: 2026-10-28 | B26: 기능 | C26: [11순위] 실행 취소 / 다시 실행 | D26: 편집 메뉴 + Ctrl+Z / Ctrl+Y(Ctrl+Shift+Z). 편집이 멈추고 0.4초 뒤 한 단계로 기록(슬라이더를 끌어도 한 번), 최대 100단계. 새로 만들기·열기·복구 때 기록 초기화. 화면 테스트: 클립 삭제 취소 → 자르기 취소 → 다시 실행 → 제목 추가 취소 | E26: 완료 | F26: 1209b67
A27: 2026-10-28 | B27: 기능 | C27: [12순위] 기본 플레이어로 열기 | D27: 미리보기 재생 바의 ↗ 버튼과 내보내기 완료 창의 '재생' 버튼 → Windows 기본 플레이어로 열기. '노래 늘어짐'이 앱 재생기 문제인지 파일 문제인지 비교 가능 | E27: 완료 | F27: 1a3c03d
A28: 2026-10-28 | B28: 기능 | C28: [13순위] 조각 캐시 | D28: 조각을 %LOCALAPPDATA%\ReelCut\cache에 저장해 두고 같은 원본·자르기·설정이면 재사용(원본 크기·수정 시각까지 비교). 최대 3GB, 오래 안 쓴 것부터 정리, 파일 메뉴 '임시 조각 지우기'. 측정(60초·컷 72개 미리보기): 19.1초 → 자막만 바꿔 다시 6.2초, 제목 추가 6.5초. 한글·작은따옴표 사용자 폴더에서도 엣지 테스트 5종 통과 | E28: 약 3배 빨라짐 | F28: bf35efd
A29: 2026-10-28 | B29: 기능 | C29: [14순위] 클립별 속도·소리 | D29: 선택한 클립의 속도(0.25~4배, 소리는 음높이 유지)와 소리 크기(0~200%)·음소거. 목록에 ⏩2배/🐢0.5배/🔇 표시, 전체 길이·비트 맞춤·자동 자막 시간 모두 속도 반영. 측정: 0.5배 16초/2배 4초/4배 2초 정확, 프레임 확인으로 원본 위치도 맞음 | E29: 완료 | F29: e6c4fab
A30: 2026-10-28 | B30: 계획 | C30: 2차 로드맵 완료 → 3차 로드맵(15~18순위) 수립 | D30: 사용자 확인이 필요한 항목(실제 자막 모델, 재생기 소리)과 편의·완성도 기능
A31: 2026-10-28 | B31: 기능 | C31: [17순위] 타임라인 막대 | D31: 미리보기 아래에 완성 영상 흐름 표시: 클립 조각(파일별 색), 컷 경계, 자막·제목·화면 속 화면 줄. 마우스를 올리면 클립 이름, 누르면 그 클립 선택 | E31: 완료 | F31: 6a031d7
A32: 2026-10-28 | B32: 기능 | C32: [18순위] 비트 강약 반영 (컷 리듬) | D32: 음악·비트 탭 '컷 리듬': 일정하게 / 센 비트에서만 / 신나는 부분은 빠르게. 비트 분석 때 비트별 세기(비트 직후 60ms 음량을 주변 8비트 최댓값과 비교)와 구간 음량(순위)을 함께 저장. 합성 곡(조용한 절+시끄러운 후렴, 4박 중 첫 박 강박) 검증: 센 비트 모드 컷의 100%가 강박, 신나는 부분 모드는 후렴 컷 33개 vs 절 14개 | E32: 완료 | F32: a203b11
A33: 2026-10-28 | B33: 버그 | C33: [18순위 중] 센 비트 판정·컷 개수 문제 2건 | D33: ① 곡 전체 순위로 세기를 매기자 후렴의 모든 박이 '세다'로 판정 → 주변 비트 대비 세기로 변경. ② 비트가 고르게 센 곡에서 '센 비트에서만'이 오히려 컷이 더 많음(70개 vs 37개) → 일정 간격보다 자주 바꾸지 않도록(36개) | E33: 수정 | F33: a203b11
A34: 2026-10-28 | B34: 계획 | C34: 4차 로드맵(19~24순위) 수립 | D34: 15·16순위는 사용자 확인 대기. 같은 기준으로 진단(오류 기록)·대규모 안정성·단축키·켄 번즈·덕킹·색감 필터 순
A35: 2026-10-28 | B35: 기능 | C35: [19순위] 오류 기록 파일 | D35: %LOCALAPPDATA%\ReelCut\logs\reelcut.log에 시작 정보, 작업 실패 상세(파이썬 추적), ffmpeg 실패 명령·출력 60줄을 기록(1MB×3개 순환). 예상 못한 오류는 안내 창(작업은 자동 저장됨 + 기록 위치), 도움말 메뉴 '오류 기록 폴더 열기' | E35: 완료 | F35: (이번 커밋)
A36: 2026-10-28 | B36: 사용자 제보 | C36: 클립 개수에 맞춰 노래 끊기 요청 | D36: 8개 영상(길이 제각각)을 N초마다 끊어 이으면 8×N초에 영상·노래가 끝나야 함 → 20순위로 바로 진행 | E36: 완료
A37: 2026-10-28 | B37: 기능 | C37: 클립 개수 × N초 영상 길이 | D37: 자르는 기준(음악 비트마다/일정한 초마다)과 영상 길이 "클립 개수 × 컷 길이" 추가. 클립마다 한 컷씩(파일 순서 또는 무작위), 노래·영상 모두 거기서 끝. 정보 줄에 완성 길이와 경고(음악이 짧음, 컷보다 짧은 클립) 표시 | E37: 완료 · 클립 8개 × 2.5초 = 0:20.0, 미리보기 20.0초, 타임라인 조각 8개 | F37: 5b7fb40
A38: 2026-10-28 | B38: 기능 | C38: 단축키 | D38: 재생 메뉴 추가: Space 재생/일시정지(글자 칸·음악 게이지에서는 원래 동작), Ctrl+←/→ 5초 이동, F5·Ctrl+R 미리보기, Ctrl+E 내보내기. 클립·작은 화면·자막·제목 목록에서 Delete로 지우기. 작업 중에는 단축키로 렌더링이 겹쳐 시작되지 않게 막음 | E38: 완료 · 화면 테스트로 키 동작 확인
A39: 2026-10-28 | B39: 버그 수정 | C39: 자막 줄 삭제가 실행 취소·자동 저장에 안 잡힘 | D39: 자막 탭에서 줄을 지워도 변경 알림이 없어 실행 취소 기록·자동 저장·타임라인 갱신이 빠졌음 → 변경 알림 추가 | E39: 수정
A40: 2026-10-28 | B40: 테스트 | C40: 대규모 프로젝트 스트레스 테스트 | D40: 720p 클립 10개 + 10분 음악(128 BPM), 1비트마다 컷 → 조각 1281개, 자막 120줄. 계획 0.0초, 렌더링 520초(4코어, 다른 작업과 동시), 메모리 178MB(앱)·462MB(ffmpeg). 9분 30초 이후에도 컷이 비트와 1프레임 이내(중앙값 0.7ms), 끝부분 소리 어긋남 ±20ms 이내 | E40: 통과 · 600.0초 정확
...

Sheet 테스트
A1: 날짜 | B1: 테스트 수 | C1: 통과 | D1: 통과율 | E1: 메모
A2: 2026-10-13 | B2: 50 | C2: 50 | D2: =IFERROR(C2/B2,0) -> 1 | E2: 비트 맞춤 수정 후
A3: 2026-10-28 | B3: 51 | C3: 51 | D3: =IFERROR(C3/B3,0) -> 1 | E3: 병렬 렌더 취소 테스트 추가
A4: 2026-10-28 | B4: 54 | C4: 54 | D4: =IFERROR(C4/B4,0) -> 1 | E4: 자동 저장 테스트 추가
A5: 2026-10-28 | B5: 58 | C5: 58 | D5: =IFERROR(C5/B5,0) -> 1 | E5: 취소 시 파일 보호, 없는 파일, 다시 연결, 오류 문구 테스트 추가
A6: 2026-10-28 | B6: 59 | C6: 59 | D6: =IFERROR(C6/B6,0) -> 1 | E6: 남은 시간 문구 테스트 추가
A7: 2026-10-28 | B7: 60 | C7: 60 | D7: =IFERROR(C7/B7,0) -> 1 | E7: 썸네일 테스트 추가
A8: 2026-10-28 | B8: 61 | C8: 61 | D8: =IFERROR(C8/B8,0) -> 1 | E8: 음량 필터 테스트 추가
A9: 2026-10-28 | B9: 62 | C9: 62 | D9: =IFERROR(C9/B9,0) -> 1 | E9: 페이드 필터 테스트 추가
A10: 2026-10-28 | B10: 67 | C10: 67 | D10: =IFERROR(C10/B10,0) -> 1 | E10: 전환 효과·길이 정확도·조각 형식 테스트 추가
A11: 2026-10-28 | B11: 70 | C11: 70 | D11: =IFERROR(C11/B11,0) -> 1 | E11: 제목 ASS·렌더 테스트 추가
A12: 2026-10-28 | B12: 72 | C12: 72 | D12: =IFERROR(C12/B12,0) -> 1 | E12: 디스크 공간·결과 검사 테스트 추가
A13: 2026-10-28 | B13: 74 | C13: 74 | D13: =IFERROR(C13/B13,0) -> 1 | E13: 실행 취소 기록 테스트 추가
... A33: 2026-10-28 | B33: 107 | C33: 107 | D33: =IFERROR(C33/B33,0) -> 1 | E33: 날짜 도장 테스트 추가
